Workbook

Sheet 요약
A1: 메가박스 단독개봉 벤치마크
A2: KOBIS 체인영화관별 상영현황 실측 · 2023-01-02 ~ 2026-08-26 수집
A3: 모수 147편 (신작 99 / 재개봉·구작 48) — 메가 최대주간 50관 이상
A5: 세그먼트별 최종 누적관객 (신작)
A6: 세그먼트 | B6: 편수 | C6: 최대 | D6: p75 | E6: 중앙값 | F6: p25 | G6: 배수 중앙값
A7: 애니메이션 | B7: =COUNT('신작'!G68:G101) | C7: =MAX('신작'!G68:G101) | D7: =QUARTILE('신작'!G68:G101,3) | E7: =MEDIAN('신작'!G68:G101) | F7: =QUARTILE('신작'!G68:G101,1) | G7: =MEDIAN('신작'!K68:K101)
A8: 공연·실황 | B8: =COUNT('신작'!G3:G12) | C8: =MAX('신작'!G3:G12) | D8: =QUARTILE('신작'!G3:G12,3) | E8: =MEDIAN('신작'!G3:G12) | F8: =QUARTILE('신작'!G3:G12,1) | G8: =MEDIAN('신작'!K3:K12)
A9: 실사 외화 | B9: =COUNT('신작'!G13:G57) | C9: =MAX('신작'!G13:G57) | D9: =QUARTILE('신작'!G13:G57,3) | E9: =MEDIAN('신작'!G13:G57) | F9: =QUARTILE('신작'!G13:G57,1) | G9: =MEDIAN('신작'!K13:K57)
A10: 실사 한국 | B10: =COUNT('신작'!G58:G67) | C10: =MAX('신작'!G58:G67) | D10: =QUARTILE('신작'!G58:G67,3) | E10: =MEDIAN('신작'!G58:G67) | F10: =QUARTILE('신작'!G58:G67,1) | G10: =MEDIAN('신작'!K58:K67)
A11: 신작 전체 | B11: =COUNT('신작'!G3:G101) | C11: =MAX('신작'!G3:G101) | D11: =QUARTILE('신작'!G3:G101,3) | E11: =MEDIAN('신작'!G3:G101) | F11: =QUARTILE('신작'!G3:G101,1) | G11: =MEDIAN('신작'!K3:K101)
A13: 개봉일 편성 (신작)
A14: 세그먼트 | B14: 개봉일 좌석 중앙값 | C14: 개봉일 스크린 중앙값 | D14: 개봉일 좌석판매율 중앙값
A15: 애니메이션 | B15: =MEDIAN('신작'!H68:H101) | C15: =MEDIAN('신작'!I68:I101) | D15: =MEDIAN('신작'!L68:L101)
A16: 공연·실황 | B16: =MEDIAN('신작'!H3:H12) | C16: =MEDIAN('신작'!I3:I12) | D16: =MEDIAN('신작'!L3:L12)
A17: 실사 외화 | B17: =MEDIAN('신작'!H13:H57) | C17: =MEDIAN('신작'!I13:I57) | D17: =MEDIAN('신작'!L13:L57)
A18: 실사 한국 | B18: =MEDIAN('신작'!H58:H67) | C18: =MEDIAN('신작'!I58:I67) | D18: =MEDIAN('신작'!L58:L67)
A21: 인 더 그레이 밴드 — 실사 외화 × 메가 150관 이상
A22: 인 더 그레이(2026-09-02 개봉, 우리 수입배급작)의 최근접 comp. 상세는 「인더그레이 밴드」 시트.
A23: 지표 | B23: 값
A24: 편수 | B24: =COUNT('인더그레이 밴드'!G3:G8)
A25: 최종 최대 | B25: =MAX('인더그레이 밴드'!G3:G8)
A26: 최종 중앙값 | B26: =MEDIAN('인더그레이 밴드'!G3:G8)
A27: 최종 최소 | B27: =MIN('인더그레이 밴드'!G3:G8)
A28: 개봉일 좌석 중앙값 | B28: =MEDIAN('인더그레이 밴드'!H3:H8)
A29: 개봉일 관객 중앙값 | B29: =MEDIAN('인더그레이 밴드'!J3:J8)
A30: 배수 중앙값 | B30: =MEDIAN('인더그레이 밴드'!K3:K8)
A32: 해석 ① 진격의 거인 완결편이 334관 메가박스 단독으로 949,711명 — 단독개봉이라 물리적으로 못 간다는 명제는 성립하지 않는다.
A33: 해석 ② 실사 외화 천장 63,767은 '단독의 한계'가 아니라, 그 급 수요의 실사 외화가 아직 단독으로 안 왔다는 표본 사실에 가깝다. 밴드는 하한 근거로 쓰고 상단은 열어둘 것.
A34: 해석 ③ 개봉일 편성(4.5만~6.3만석)은 6편이 비슷한데 최종은 3.7배 갈린다 → 편성 규모보다 개봉일 관객수·첫주 유지율의 판별력이 크다.
A35: 주의 ① 워페어·극장판 기븐은 상영중이라 최종 아님(노란 행).
A36: 주의 ② 판정 커버리지는 4대 체인(CGV·롯데시네마·메가박스·씨네Q)뿐 — 독립극장·예술전용관 상영은 보이지 않는다.

Sheet 전체
A1: ※ 판정: KOBIS 「체인영화관별 상영현황」 실측 — 오리지널 런 구간에서 CGV·롯데 편성 0 & 메가박스 편성 有 (씨네Q 허용, 메가 최대주간 50관 이상). 노란 행 = 상영중이라 최종 아님.
A2: 영화명 | B2: 개봉일 | C2: 원개봉일 | D2: 구분 | E2: 세그먼트 | F2: 상영상태 | G2: 누적관객 | H2: 개봉일좌석수 | I2: 개봉일스크린수 | J2: 개봉일관객수 | K2: 배수(누적÷개봉일좌석) | L2: 개봉일 좌석판매율 | M2: 메가최대일간스크린 | N2: 평균스크린 | O2: 스크린당좌석 | P2: 상영주수 | Q2: 단독런시작 | R2: 단독런종료 | S2: 장르 | T2: 대표국적 | U2: 배급사
A3: 극장판 진격의 거인 완결편 더 라스트 어택 | B3: 2025-03-13 | C3: 2025-03-13 | D3: 신작 | E3: 애니메이션 | F3: 종영 | G3: 949711 | H3: 116840 | I3: 335 | J3: 37674 | K3: =IFERROR(G3/H3,"") | L3: =IFERROR(J3/H3,"") | M3: 334 | N3: 81.2 | O3: 306 | P3: 35 | Q3: 2025-03-03 | R3: 2025-11-02 | S3: 애니메이션 | T3: 일본 | U3: (주)애니플러스
A4: 룩백 | B4: 2024-09-05 | C4: 2024-09-05 | D4: 신작 | E4: 애니메이션 | F4: 종영 | G4: 301976 | H4: 116966 | I4: 184 | J4: 16206 | K4: =IFERROR(G4/H4,"") | L4: =IFERROR(J4/H4,"") | M4: 220 | N4: 100.1 | O4: 253 | P4: 19 | Q4: 2024-08-26 | R4: 2025-01-05 | S4: 애니메이션 | T4: 일본 | U4: 메가박스중앙(주)
A5: 러브레터 | B5: 2025-01-01 | C5: 1999-11-20 | D5: 재개봉/구작 | E5: 실사 외화 | F5: 종영 | G5: 116561 | H5: 35619 | I5: 181 | J5: 14957 | K5: =IFERROR(G5/H5,"") | L5: =IFERROR(J5/H5,"") | M5: 169 | N5: 70.4 | O5: 188 | P5: 13 | Q5: 2024-12-23 | R5: 2025-03-23 | S5: 멜로/로맨스,드라마 | T5: 일본 | U5: 워터홀컴퍼니(주),주식회사 왓챠,와이드 릴리즈(주),(주)제이앤씨미디어그룹,(유)조이앤시네마,(주)팝엔터테인먼트
A6: 프랑켄슈타인 : 더 뮤지컬 라이브 | B6: 2025-09-18 | C6: 2025-09-18 | D6: 신작 | E6: 공연·실황 | F6: 종영 | G6: 93574 | H6: 20923 | I6: 19 | J6: 4789 | K6: =IFERROR(G6/H6,"") | L6: =IFERROR(J6/H6,"") | M6: 141 | N6: 47.1 | O6: 219 | P6: 14 | Q6: 2025-09-08 | R6: 2025-12-14 | S6: 공연 | T6: 한국 | U6: (주)위즈온센,메가박스중앙(주)
A7: 극장판 프로젝트 세카이 부서진 세카이와 전해지지 않는 미쿠의 노래 | B7: 2025-05-29 | C7: 2025-05-29 | D7: 신작 | E7: 애니메이션 | F7: 종영 | G7: 82581 | H7: 43901 | I7: 158 | J7: 7510 | K7: =IFERROR(G7/H7,"") | L7: =IFERROR(J7/H7,"") | M7: 157 | N7: 48 | O7: 160 | P7: 15 | Q7: 2025-05-26 | R7: 2025-09-07 | S7: 애니메이션 | T7: 일본 | U7: (주)애니플러스
A8: 우마무스메 프리티 더비 새로운 시대의 문 | B8: 2024-07-11 | C8: 2024-07-11 | D8: 신작 | E8: 애니메이션 | F8: 종영 | G8: 64612 | H8: 37649 | I8: 127 | J8: 6421 | K8: =IFERROR(G8/H8,"") | L8: =IFERROR(J8/H8,"") | M8: 126 | N8: 51 | O8: 177 | P8: 11 | Q8: 2024-07-01 | R8: 2024-09-15 | S8: 애니메이션 | T8: 일본 | U8: (주)애니플러스
A9: 머티리얼리스트 | B9: 2025-08-08 | C9: 2025-08-08 | D9: 신작 | E9: 실사 외화 | F9: 종영 | G9: 63767 | H9: 62670 | I9: 166 | J9: 7585 | K9: =IFERROR(G9/H9,"") | L9: =IFERROR(J9/H9,"") | M9: 157 | N9: 63.6 | O9: 213 | P9: 9 | Q9: 2025-07-28 | R9: 2025-09-28 | S9: 멜로/로맨스,코미디 | T9: 미국 | U9: 소니픽쳐스엔터테인먼트코리아주식회사극장배급지점
A10: 라스트 마일 | B10: 2025-03-26 | C10: 2025-03-26 | D10: 신작 | E10: 실사 외화 | F10: 종영 | G10: 53013 | H10: 42700 | I10: 148 | J10: 4031 | K10: =IFERROR(G10/H10,"") | L10: =IFERROR(J10/H10,"") | M10: 147 | N10: 49.9 | O10: 202 | P10: 11 | Q10: 2025-03-17 | R10: 2025-06-01 | S10: 스릴러,드라마 | T10: 일본 | U10: (주)엠디에스스피어
A11: 첫 번째 키스 | B11: 2025-02-26 | C11: 2025-02-26 | D11: 신작 | E11: 실사 외화 | F11: 종영 | G11: 49143 | H11: 61274 | I11: 184 | J11: 6199 | K11: =IFERROR(G11/H11,"") | L11: =IFERROR(J11/H11,"") | M11: 178 | N11: 64.2 | O11: 208 | P11: 8 | Q11: 2025-02-24 | R11: 2025-04-20 | S11: 드라마,멜로/로맨스 | T11: 일본 | U11: 메가박스중앙(주)
A12: 엘리자벳: 더 뮤지컬 라이브 | B12: 2024-10-16 | C12: 2024-10-16 | D12: 신작 | E12: 공연·실황 | F12: 종영 | G12: 47522 | H12: 19245 | I12: 18 | J12: 2659 | K12: =IFERROR(G12/H12,"") | L12: =IFERROR(J12/H12,"") | M12: 118 | N12: 57.3 | O12: 219 | P12: 8 | Q12: 2024-10-14 | R12: 2024-12-08 | S12: 공연,뮤지컬 | T12: 한국 | U12: (주)위즈온센,메가박스중앙(주)
A13: 극장판 아이돌리쉬 세븐; 라이브 4비트 비욘드 더 피리어드 - 데이 2 | B13: 2023-10-19 | C13: 2023-10-19 | D13: 신작 | E13: 애니메이션 | F13: 종영 | G13: 46677 | H13: 10330 | I13: 78 | J13: 1155 | K13: =IFERROR(G13/H13,"") | L13: =IFERROR(J13/H13,"") | M13: 78 | N13: 8.2 | O13: 158 | P13: 47 | Q13: 2023-10-09 | R13: 2024-09-01 | S13: 애니메이션 | T13: 일본 | U13: 메가박스중앙(주)
A14: 쇼생크 탈출 | B14: 2024-05-08 | C14: 1995-02-04 | D14: 재개봉/구작 | E14: 실사 외화 | F14: 종영 | G14: 46108 | H14: 36526 | I14: 123 | J14: 5972 | K14: =IFERROR(G14/H14,"") | L14: =IFERROR(J14/H14,"") | M14: 107 | N14: 36.3 | O14: 206 | P14: 11 | Q14: 2024-04-29 | R14: 2024-07-14 | S14: 드라마 | T14: 미국 | U14: 롯데컬처웍스(주)롯데시네마,(주)팝엔터테인먼트,THE 픽쳐스
... A50: 코코 | B50: 2024-05-30 | C50: 2018-01-11 | D50: 재개봉/구작 | E50: 애니메이션 | F50: 종영 | G50: 16917 | H50: 36952 | I50: 104 | J50: 3998 | K50: =IFERROR(G50/H50,"") | L50: =IFERROR(J50/H50,"") | M50: 104 | N50: 88 | O50: 250 | P50: 3 | Q50: 2024-05-27 | R50: 2024-06-16 | S50: 애니메이션 | T50: 미국 | U50: 월트디즈니컴퍼니코리아 유한책임회사
A51: 첫여름 | B51: 2025-08-06 | D51: 재개봉/구작 | E51: 실사 한국 | F51: 종영 | G51: 16906 | H51: 13702 | I51: 85 | J51: 1595 | K51: =IFERROR(G51/H51,"") | L51: =IFERROR(J51/H51,"") | M51: 85 | N51: 32.3 | O51: 132 | P51: 10 | Q51: 2025-07-28 | R51: 2025-10-05 | S51: 드라마 | T51: 한국 | U51: 한국영화아카데미
A52: 가타카 | B52: 2025-11-20 | C52: 1998-05-02 | D52: 재개봉/구작 | E52: 실사 외화 | F52: 종영 | G52: 16560 | H52: 15383 | I52: 71 | J52: 1388 | K52: =IFERROR(G52/H52,"") | L52: =IFERROR(J52/H52,"") | M52: 72 | N52: 26.7 | O52: 148 | P52: 7 | Q52: 2025-11-17 | R52: 2026-01-04 | S52: SF,드라마,미스터리,스릴러 | T52: 미국
A53: 극장판 츠루네: 시작의 한 발 | B53: 2024-02-21 | C53: 2024-02-21 | D53: 신작 | E53: 애니메이션 | F53: 종영 | G53: 16531 | H53: 33564 | I53: 119 | J53: 3654 | K53: =IFERROR(G53/H53,"") | L53: =IFERROR(J53/H53,"") | M53: 118 | N53: 34.3 | O53: 149 | P53: 8 | Q53: 2024-02-12 | R53: 2024-04-07 | S53: 애니메이션 | T53: 일본 | U53: (주)라이크콘텐츠
A54: 중경삼림 | B54: 2024-02-14 | C54: 1995-09-02 | D54: 재개봉/구작 | E54: 실사 외화 | F54: 종영 | G54: 16102 | H54: 6776 | I54: 53 | J54: 1390 | K54: =IFERROR(G54/H54,"") | L54: =IFERROR(J54/H54,"") | M54: 53 | N54: 11.3 | O54: 111 | P54: 14 | Q54: 2024-02-12 | R54: 2024-05-19 | S54: 드라마 | T54: 홍콩 | U54: (주)디스테이션
A55: 해피 투게더 | B55: 2023-03-30 | C55: 1998-08-22 | D55: 재개봉/구작 | E55: 실사 외화 | F55: 종영 | G55: 15835 | H55: 36350 | I55: 140 | J55: 7147 | K55: =IFERROR(G55/H55,"") | L55: =IFERROR(J55/H55,"") | M55: 129 | N55: 42.1 | O55: 186 | P55: 5 | Q55: 2023-03-27 | R55: 2023-04-30 | S55: 드라마,멜로/로맨스 | T55: 홍콩 | U55: (주)디스테이션
A56: 히어 | B56: 2025-02-19 | C56: 2025-02-19 | D56: 신작 | E56: 실사 외화 | F56: 종영 | G56: 15435 | H56: 50640 | I56: 144 | J56: 3227 | K56: =IFERROR(G56/H56,"") | L56: =IFERROR(J56/H56,"") | M56: 112 | N56: 44.2 | O56: 212 | P56: 6 | Q56: 2025-02-10 | R56: 2025-03-23 | S56: 드라마 | T56: 미국 | U56: 메가박스중앙(주),(주)이놀미디어
A57: 영웅: 라이브 인 시네마 | B57: 2024-08-21 | C57: 2024-08-21 | D57: 신작 | E57: 공연·실황 | F57: 종영 | G57: 15141 | H57: 6291 | I57: 21 | J57: 803 | K57: =IFERROR(G57/H57,"") | L57: =IFERROR(J57/H57,"") | M57: 98 | N57: 24.5 | O57: 154 | P57: 18 | Q57: 2024-08-12 | R57: 2024-12-15 | S57: 공연,뮤지컬 | T57: 한국 | U57: (주)위즈온센,메가박스중앙(주)
A58: 철도원 | B58: 2026-01-07 | C58: 2000-02-04 | D58: 재개봉/구작 | E58: 실사 외화 | F58: 종영 | G58: 14997 | H58: 24542 | I58: 127 | J58: 1289 | K58: =IFERROR(G58/H58,"") | L58: =IFERROR(J58/H58,"") | M58: 123 | N58: 53.5 | O58: 147 | P58: 5 | Q58: 2026-01-05 | R58: 2026-02-08 | S58: 가족,드라마 | T58: 일본 | U58: 와이드 릴리즈(주)
A59: 엑소시스트: 더 바티칸 | B59: 2023-05-10 | C59: 2023-05-10 | D59: 신작 | E59: 실사 외화 | F59: 종영 | G59: 14639 | H59: 43011 | I59: 129 | J59: 2373 | K59: =IFERROR(G59/H59,"") | L59: =IFERROR(J59/H59,"") | M59: 127 | N59: 54.2 | O59: 224 | P59: 5 | Q59: 2023-05-01 | R59: 2023-06-04 | S59: 공포(호러) | T59: 미국 | U59: 소니픽쳐스엔터테인먼트코리아주식회사극장배급지점
A60: 슈퍼소닉 | B60: 2025-08-29 | C60: 2016-11-24 | D60: 재개봉/구작 | E60: 실사 외화 | F60: 종영 | G60: 14607 | H60: 25786 | I60: 124 | J60: 3774 | K60: =IFERROR(G60/H60,"") | L60: =IFERROR(J60/H60,"") | M60: 93 | N60: 39.8 | O60: 158 | P60: 6 | Q60: 2025-08-18 | R60: 2025-09-28 | S60: 다큐멘터리 | T60: 영국 | U60: (주)레드아이스 엔터테인먼트,주식회사 씨네룩스
A61: 커미션 | B61: 2025-07-16 | C61: 2025-07-16 | D61: 신작 | E61: 실사 한국 | F61: 종영 | G61: 14415 | H61: 22780 | I61: 127 | J61: 2688 | K61: =IFERROR(G61/H61,"") | L61: =IFERROR(J61/H61,"") | M61: 126 | N61: 49.1 | O61: 142 | P61: 5 | Q61: 2025-07-07 | R61: 2025-08-10 | S61: 미스터리,스릴러 | T61: 한국 | U61: (주)팬엔터테인먼트,(주)미디어캐슬
A62: 씰벤져스 : 용감한 바다특공대 | B62: 2023-09-27 | C62: 2023-09-27 | D62: 신작 | E62: 애니메이션 | F62: 종영 | G62: 14209 | H62: 10144 | I62: 79 | J62: 608 | K62: =IFERROR(G62/H62,"") | L62: =IFERROR(J62/H62,"") | M62: 109 | N62: 35 | O62: 145 | P62: 8 | Q62: 2023-09-18 | R62: 2023-11-12 | S62: 애니메이션,액션,코미디,어드벤처 | T62: 미국 | U62: (주)무비다이브
A63: 오피셜히게단디즘 라이브 앳 스타디움 2025 | B63: 2026-04-02 | C63: 2026-04-02 | D63: 신작 | E63: 공연·실황 | F63: 종영 | G63: 13842 | H63: 14556 | I63: 58 | J63: 3178 | K63: =IFERROR(G63/H63,"") | L63: =IFERROR(J63/H63,"") | M63: 58 | N63: 19.2 | O63: 195 | P63: 8 | Q63: 2026-03-30 | R63: 2026-05-24 | S63: 공연 | T63: 일본 | U63: (주)영화사 그램
A64: 크리스마스에 기적을 만날 확률 | B64: 2024-12-11 | C64: 2007-12-12 | D64: 재개봉/구작 | E64: 애니메이션 | F64: 종영 | G64: 13312 | H64: 21229 | I64: 117 | J64: 1827 | K64: =IFERROR(G64/H64,"") | L64: =IFERROR(J64/H64,"") | M64: 110 | N64: 35.6 | O64: 139 | P64: 7 | Q64: 2024-12-09 | R64: 2025-01-26 | S64: 애니메이션,드라마,액션 | T64: 일본 | U64: (주)팝엔터테인먼트,롯데쇼핑㈜롯데엔터테인먼트
... A71: 영화 러브 라이브! 니지가사키 학원 스쿨 아이돌 동호회 완결편 제1장 | B71: 2025-02-06 | C71: 2025-02-06 | D71: 신작 | E71: 애니메이션 | F71: 종영 | G71: 10914 | H71: 26756 | I71: 110 | J71: 1620 | K71: =IFERROR(G71/H71,"") | L71: =IFERROR(J71/H71,"") | M71: 110 | N71: 26 | O71: 160 | P71: 11 | Q71: 2025-02-03 | R71: 2025-04-20 | S71: 애니메이션 | T71: 일본 | U71: (주)애니플러스
A72: 택시 드라이버 | B72: 2025-04-09 | C72: 1989-02-17 | D72: 재개봉/구작 | E72: 실사 외화 | F72: 종영 | G72: 10856 | H72: 20556 | I72: 82 | J72: 2006 | K72: =IFERROR(G72/H72,"") | L72: =IFERROR(J72/H72,"") | M72: 83 | N72: 61.7 | O72: 164 | P72: 4 | Q72: 2025-04-07 | R72: 2025-05-04 | S72: 드라마,스릴러 | T72: 미국
A73: 몽키맨 | B73: 2024-06-19 | C73: 2024-06-19 | D73: 신작 | E73: 실사 외화 | F73: 종영 | G73: 10490 | H73: 35002 | I73: 146 | J73: 1196 | K73: =IFERROR(G73/H73,"") | L73: =IFERROR(J73/H73,"") | M73: 75 | N73: 34.6 | O73: 186 | P73: 5 | Q73: 2024-06-10 | R73: 2024-07-14 | S73: 액션,스릴러 | T73: 미국 | U73: 유니버설픽쳐스인터내셔널 코리아(유)
A74: 에드워드 호퍼 | B74: 2024-11-27 | C74: 2024-11-27 | D74: 신작 | E74: 실사 외화 | F74: 종영 | G74: 10471 | H74: 15473 | I74: 111 | J74: 1422 | K74: =IFERROR(G74/H74,"") | L74: =IFERROR(J74/H74,"") | M74: 77 | N74: 30.8 | O74: 125 | P74: 5 | Q74: 2024-11-25 | R74: 2024-12-29 | S74: 다큐멘터리 | T74: 영국 | U74: 영화사빅
A75: 대결! 애니메이션 | B75: 2024-03-06 | C75: 2024-03-06 | D75: 신작 | E75: 실사 외화 | F75: 종영 | G75: 10118 | H75: 21316 | I75: 103 | J75: 2122 | K75: =IFERROR(G75/H75,"") | L75: =IFERROR(J75/H75,"") | M75: 102 | N75: 25.8 | O75: 157 | P75: 9 | Q75: 2024-02-19 | R75: 2024-04-21 | S75: 드라마 | T75: 일본 | U75: (주)빌리언스플러스,(주)블루라벨픽쳐스
A76: 금지된 장난 | B76: 2024-06-05 | C76: 2024-06-05 | D76: 신작 | E76: 실사 외화 | F76: 종영 | G76: 10064 | H76: 26902 | I76: 118 | J76: 2228 | K76: =IFERROR(G76/H76,"") | L76: =IFERROR(J76/H76,"") | M76: 74 | N76: 42.5 | O76: 172 | P76: 4 | Q76: 2024-06-03 | R76: 2024-06-30 | S76: 공포(호러) | T76: 일본 | U76: 와이드 릴리즈(주)
A77: 레옹 | B77: 2024-04-22 | C77: 1995-02-18 | D77: 재개봉/구작 | E77: 실사 외화 | F77: 종영 | G77: 10030 | H77: 18828 | I77: 94 | J77: 1129 | K77: =IFERROR(G77/H77,"") | L77: =IFERROR(J77/H77,"") | M77: 88 | N77: 20.9 | O77: 140 | P77: 5 | Q77: 2024-04-22 | R77: 2024-05-26 | S77: 액션,범죄 | T77: 프랑스 | U77: 와이드 릴리즈(주),(주)제이앤씨미디어그룹,(주)팝파트너스
A78: 좀비 랜드 사가: 유메긴가 파라다이스 | B78: 2026-03-04 | C78: 2026-03-04 | D78: 신작 | E78: 애니메이션 | F78: 종영 | G78: 9851 | H78: 15447 | I78: 104 | J78: 804 | K78: =IFERROR(G78/H78,"") | L78: =IFERROR(J78/H78,"") | M78: 100 | N78: 25.4 | O78: 118 | P78: 11 | Q78: 2026-03-02 | R78: 2026-05-17 | S78: 애니메이션 | T78: 일본 | U78: 메가박스중앙(주)
A79: 그랜드 부다페스트 호텔 | B79: 2026-04-08 | C79: 2014-03-20 | D79: 재개봉/구작 | E79: 실사 외화 | F79: 종영 | G79: 9624 | H79: 20307 | I79: 81 | J79: 3077 | K79: =IFERROR(G79/H79,"") | L79: =IFERROR(J79/H79,"") | M79: 81 | N79: 23.8 | O79: 190 | P79: 5 | Q79: 2026-04-06 | R79: 2026-05-10 | S79: 미스터리,어드벤처 | T79: 미국 | U79: (주)피터팬픽쳐스,이십세기폭스코리아(주),월트디즈니컴퍼니코리아 유한책임회사
A80: 라이프 오브 파이 | B80: 2026-03-25 | C80: 2013-01-01 | D80: 재개봉/구작 | E80: 실사 외화 | F80: 종영 | G80: 9540 | H80: 16920 | I80: 58 | J80: 3065 | K80: =IFERROR(G80/H80,"") | L80: =IFERROR(J80/H80,"") | M80: 58 | N80: 26 | O80: 214 | P80: 4 | Q80: 2026-03-23 | R80: 2026-04-19 | S80: 어드벤처,드라마 | T80: 미국 | U80: 월트디즈니컴퍼니코리아 유한책임회사,주식회사 해리슨앤컴퍼니,이십세기폭스코리아(주)
A81: 극장판 다이노맨: 공룡산의 비밀 | B81: 2025-07-25 | C81: 2025-07-25 | D81: 신작 | E81: 애니메이션 | F81: 종영 | G81: 9288 | H81: 8031 | I81: 64 | J81: 875 | K81: =IFERROR(G81/H81,"") | L81: =IFERROR(J81/H81,"") | M81: 81 | N81: 13.6 | O81: 113 | P81: 11 | Q81: 2025-07-07 | R81: 2025-09-21 | S81: 애니메이션 | T81: 한국 | U81: (주)엠디에스스피어
...

Sheet 신작
A1: ※ 판정: KOBIS 「체인영화관별 상영현황」 실측 — 오리지널 런 구간에서 CGV·롯데 편성 0 & 메가박스 편성 有 (씨네Q 허용, 메가 최대주간 50관 이상). 노란 행 = 상영중이라 최종 아님. / 개봉일 = KOBIS 개봉일
A2: 영화명 | B2: 개봉일 | C2: 원개봉일 | D2: 구분 | E2: 세그먼트 | F2: 상영상태 | G2: 누적관객 | H2: 개봉일좌석수 | I2: 개봉일스크린수 | J2: 개봉일관객수 | K2: 배수(누적÷개봉일좌석) | L2: 개봉일 좌석판매율 | M2: 메가최대일간스크린 | N2: 평균스크린 | O2: 스크린당좌석 | P2: 상영주수 | Q2: 단독런시작 | R2: 단독런종료 | S2: 장르 | T2: 대표국적 | U2: 배급사
A3: 프랑켄슈타인 : 더 뮤지컬 라이브 | B3: 2025-09-18 | C3: 2025-09-18 | D3: 신작 | E3: 공연·실황 | F3: 종영 | G3: 93574 | H3: 20923 | I3: 19 | J3: 4789 | K3: =IFERROR(G3/H3,"") | L3: =IFERROR(J3/H3,"") | M3: 141 | N3: 47.1 | O3: 219 | P3: 14 | Q3: 2025-09-08 | R3: 2025-12-14 | S3: 공연 | T3: 한국 | U3: (주)위즈온센,메가박스중앙(주)
A4: 엘리자벳: 더 뮤지컬 라이브 | B4: 2024-10-16 | C4: 2024-10-16 | D4: 신작 | E4: 공연·실황 | F4: 종영 | G4: 47522 | H4: 19245 | I4: 18 | J4: 2659 | K4: =IFERROR(G4/H4,"") | L4: =IFERROR(J4/H4,"") | M4: 118 | N4: 57.3 | O4: 219 | P4: 8 | Q4: 2024-10-14 | R4: 2024-12-08 | S4: 공연,뮤지컬 | T4: 한국 | U4: (주)위즈온센,메가박스중앙(주)
A5: 마이 샤이니 월드 | B5: 2023-11-03 | C5: 2023-11-03 | D5: 신작 | E5: 공연·실황 | F5: 종영 | G5: 26480 | H5: 15156 | I5: 17 | J5: 3129 | K5: =IFERROR(G5/H5,"") | L5: =IFERROR(J5/H5,"") | M5: 93 | N5: 27 | O5: 243 | P5: 12 | Q5: 2023-10-23 | R5: 2024-01-14 | S5: 공연,다큐멘터리 | T5: 한국 | U5: 메가박스중앙(주)
A6: 어쩌면 해피엔딩 | B6: 2025-10-02 | C6: 2025-10-02 | D6: 신작 | E6: 공연·실황 | F6: 종영 | G6: 25292 | H6: 35575 | I6: 147 | J6: 1527 | K6: =IFERROR(G6/H6,"") | L6: =IFERROR(J6/H6,"") | M6: 109 | N6: 34.8 | O6: 140 | P6: 10 | Q6: 2025-09-29 | R6: 2025-12-07 | S6: 뮤지컬,멜로/로맨스 | T6: 한국 | U6: (주)키노필름,(주)아센디오,(주)영화특별시에스엠씨,(주)로드쇼플러스
A7: 뮤지컬 장수탕 선녀님 | B7: 2026-03-26 | C7: 2026-03-26 | D7: 신작 | E7: 공연·실황 | F7: 종영 | G7: 18207 | H7: 14201 | I7: 89 | J7: 737 | K7: =IFERROR(G7/H7,"") | L7: =IFERROR(J7/H7,"") | M7: 89 | N7: 30.5 | O7: 128 | P7: 10 | Q7: 2026-03-16 | R7: 2026-05-24 | S7: 뮤지컬,공연 | T7: 한국 | U7: 메가박스중앙(주),(주)영화사 그램
A8: 영웅: 라이브 인 시네마 | B8: 2024-08-21 | C8: 2024-08-21 | D8: 신작 | E8: 공연·실황 | F8: 종영 | G8: 15141 | H8: 6291 | I8: 21 | J8: 803 | K8: =IFERROR(G8/H8,"") | L8: =IFERROR(J8/H8,"") | M8: 98 | N8: 24.5 | O8: 154 | P8: 18 | Q8: 2024-08-12 | R8: 2024-12-15 | S8: 공연,뮤지컬 | T8: 한국 | U8: (주)위즈온센,메가박스중앙(주)
A9: 오피셜히게단디즘 라이브 앳 스타디움 2025 | B9: 2026-04-02 | C9: 2026-04-02 | D9: 신작 | E9: 공연·실황 | F9: 종영 | G9: 13842 | H9: 14556 | I9: 58 | J9: 3178 | K9: =IFERROR(G9/H9,"") | L9: =IFERROR(J9/H9,"") | M9: 58 | N9: 19.2 | O9: 195 | P9: 8 | Q9: 2026-03-30 | R9: 2026-05-24 | S9: 공연 | T9: 일본 | U9: (주)영화사 그램
A10: 2017 방탄소년단 라이브 트릴로지 에피소드 3 윙스 투어 더 파이널 리마스터링 | B10: 2025-09-23 | C10: 2025-09-23 | D10: 신작 | E10: 공연·실황 | F10: 종영 | G10: 5209 | H10: 285 | I10: 1 | J10: 150 | K10: =IFERROR(G10/H10,"") | L10: =IFERROR(J10/H10,"") | M10: 57 | N10: 29 | O10: 152 | P10: 5 | Q10: 2025-09-22 | R10: 2025-10-26 | S10: 공연 | T10: 한국 | U10: 메가박스중앙(주)
A11: 2019 방탄소년단 월드 투어 '러브 유어셀프 : 스피크 유어셀프' 런던 리마스터링 | B11: 2025-09-23 | C11: 2025-09-23 | D11: 신작 | E11: 공연·실황 | F11: 종영 | G11: 5163 | H11: 285 | I11: 1 | J11: 150 | K11: =IFERROR(G11/H11,"") | L11: =IFERROR(J11/H11,"") | M11: 80 | N11: 26.9 | O11: 126 | P11: 5 | Q11: 2025-09-22 | R11: 2025-10-26 | S11: 공연 | T11: 한국 | U11: 메가박스중앙(주)
A12: 2021 방탄소년단 머스터 소우주 리마스터링 | B12: 2025-09-23 | C12: 2025-09-23 | D12: 신작 | E12: 공연·실황 | F12: 종영 | G12: 3404 | H12: 285 | I12: 1 | J12: 150 | K12: =IFERROR(G12/H12,"") | L12: =IFERROR(J12/H12,"") | M12: 74 | N12: 24.1 | O12: 126 | P12: 5 | Q12: 2025-09-22 | R12: 2025-10-26 | S12: 공연 | T12: 한국 | U12: 메가박스중앙(주)
A13: 머티리얼리스트 | B13: 2025-08-08 | C13: 2025-08-08 | D13: 신작 | E13: 실사 외화 | F13: 종영 | G13: 63767 | H13: 62670 | I13: 166 | J13: 7585 | K13: =IFERROR(G13/H13,"") | L13: =IFERROR(J13/H13,"") | M13: 157 | N13: 63.6 | O13: 213 | P13: 9 | Q13: 2025-07-28 | R13: 2025-09-28 | S13: 멜로/로맨스,코미디 | T13: 미국 | U13: 소니픽쳐스엔터테인먼트코리아주식회사극장배급지점
A14: 라스트 마일 | B14: 2025-03-26 | C14: 2025-03-26 | D14: 신작 | E14: 실사 외화 | F14: 종영 | G14: 53013 | H14: 42700 | I14: 148 | J14: 4031 | K14: =IFERROR(G14/H14,"") | L14: =IFERROR(J14/H14,"") | M14: 147 | N14: 49.9 | O14: 202 | P14: 11 | Q14: 2025-03-17 | R14: 2025-06-01 | S14: 스릴러,드라마 | T14: 일본 | U14: (주)엠디에스스피어
... A101: 극장판 나와 로보코 | B101: 2025-11-26 | C101: 2025-11-26 | D101: 신작 | E101: 애니메이션 | F101: 종영 | G101: 933 | H101: 10564 | I101: 74 | J101: 181 | K101: =IFERROR(G101/H101,"") | L101: =IFERROR(J101/H101,"") | M101: 74 | N101: 26 | O101: 122 | P101: 3 | Q101: 2025-11-24 | R101: 2025-12-14 | S101: 애니메이션 | T101: 일본 | U101: 에스엠지홀딩스 주식회사

Sheet 재개봉·구작
A1: ※ 개봉일 = 재개봉일 실측(런 내 스크린이 피크 30% 도달 첫날). 원개봉일은 별도 컬럼.
A2: 영화명 | B2: 개봉일 | C2: 원개봉일 | D2: 구분 | E2: 세그먼트 | F2: 상영상태 | G2: 누적관객 | H2: 개봉일좌석수 | I2: 개봉일스크린수 | J2: 개봉일관객수 | K2: 배수(누적÷개봉일좌석) | L2: 개봉일 좌석판매율 | M2: 메가최대일간스크린 | N2: 평균스크린 | O2: 스크린당좌석 | P2: 상영주수 | Q2: 단독런시작 | R2: 단독런종료 | S2: 장르 | T2: 대표국적 | U2: 배급사
A3: 러브레터 | B3: 2025-01-01 | C3: 1999-11-20 | D3: 재개봉/구작 | E3: 실사 외화 | F3: 종영 | G3: 116561 | H3: 35619 | I3: 181 | J3: 14957 | K3: =IFERROR(G3/H3,"") | L3: =IFERROR(J3/H3,"") | M3: 169 | N3: 70.4 | O3: 188 | P3: 13 | Q3: 2024-12-23 | R3: 2025-03-23 | S3: 멜로/로맨스,드라마 | T3: 일본 | U3: 워터홀컴퍼니(주),주식회사 왓챠,와이드 릴리즈(주),(주)제이앤씨미디어그룹,(유)조이앤시네마,(주)팝엔터테인먼트
A4: 쇼생크 탈출 | B4: 2024-05-08 | C4: 1995-02-04 | D4: 재개봉/구작 | E4: 실사 외화 | F4: 종영 | G4: 46108 | H4: 36526 | I4: 123 | J4: 5972 | K4: =IFERROR(G4/H4,"") | L4: =IFERROR(J4/H4,"") | M4: 107 | N4: 36.3 | O4: 206 | P4: 11 | Q4: 2024-04-29 | R4: 2024-07-14 | S4: 드라마 | T4: 미국 | U4: 롯데컬처웍스(주)롯데시네마,(주)팝엔터테인먼트,THE 픽쳐스
A5: 라이언 일병 구하기 | B5: 2025-06-25 | C5: 1998-09-12 | D5: 재개봉/구작 | E5: 실사 외화 | F5: 종영 | G5: 31942 | H5: 38304 | I5: 163 | J5: 3958 | K5: =IFERROR(G5/H5,"") | L5: =IFERROR(J5/H5,"") | M5: 160 | N5: 42.7 | O5: 164 | P5: 10 | Q5: 2025-06-16 | R5: 2025-08-24 | S5: 드라마,액션,전쟁 | T5: 미국 | U5: 와이드 릴리즈(주)
A6: 퍼펙트 블루 | B6: 2025-09-11 | C6: 2004-05-26 | D6: 재개봉/구작 | E6: 애니메이션 | F6: 종영 | G6: 28948 | H6: 29900 | I6: 138 | J6: 4319 | K6: =IFERROR(G6/H6,"") | L6: =IFERROR(J6/H6,"") | M6: 135 | N6: 45.3 | O6: 171 | P6: 7 | Q6: 2025-09-08 | R6: 2025-10-26 | S6: 애니메이션,미스터리 | T6: 일본 | U6: (주)디스테이션,(주)튜브엔터테인먼트
A7: 미드나잇 인 파리 | B7: 2025-02-12 | C7: 2012-07-05 | D7: 재개봉/구작 | E7: 실사 외화 | F7: 종영 | G7: 23454 | H7: 34355 | I7: 136 | J7: 2779 | K7: =IFERROR(G7/H7,"") | L7: =IFERROR(J7/H7,"") | M7: 141 | N7: 58.7 | O7: 174 | P7: 8 | Q7: 2025-02-03 | R7: 2025-03-30 | S7: 코미디,멜로/로맨스,판타지 | T7: 미국 | U7: (주)디스테이션,(주)드림팩트엔터테인먼트,(주)나이너스엔터테인먼트
A8: 컨택트 | B8: 2024-11-13 | C8: 2017-02-02 | D8: 재개봉/구작 | E8: 실사 외화 | F8: 종영 | G8: 21575 | H8: 21161 | I8: 78 | J8: 4221 | K8: =IFERROR(G8/H8,"") | L8: =IFERROR(J8/H8,"") | M8: 90 | N8: 40.1 | O8: 181 | P8: 5 | Q8: 2024-11-11 | R8: 2024-12-15 | S8: SF,드라마,스릴러 | T8: 미국 | U8: 유니버설픽쳐스인터내셔널 코리아(유)
A9: 패왕별희 디 오리지널 | B9: 2024-03-27 | C9: 2017-03-30 | D9: 재개봉/구작 | E9: 실사 외화 | F9: 종영 | G9: 20234 | H9: 18985 | I9: 103 | J9: 5922 | K9: =IFERROR(G9/H9,"") | L9: =IFERROR(J9/H9,"") | M9: 99 | N9: 34.8 | O9: 147 | P9: 6 | Q9: 2024-03-25 | R9: 2024-05-05 | S9: 드라마,멜로/로맨스 | T9: 중국 | U9: 와이드 릴리즈(주),(주)제이앤씨미디어그룹,(주)드림팩트엔터테인먼트
A10: 마당을 나온 암탉 | B10: 2025-01-22 | C10: 2011-07-28 | D10: 재개봉/구작 | E10: 애니메이션 | F10: 종영 | G10: 18008 | H10: 23255 | I10: 131 | J10: 954 | K10: =IFERROR(G10/H10,"") | L10: =IFERROR(J10/H10,"") | M10: 117 | N10: 41.1 | O10: 132 | P10: 10 | Q10: 2025-01-06 | R10: 2025-03-16 | S10: 애니메이션 | T10: 한국 | U10: 메가박스중앙(주),롯데쇼핑㈜롯데엔터테인먼트
A11: 코코 | B11: 2024-05-30 | C11: 2018-01-11 | D11: 재개봉/구작 | E11: 애니메이션 | F11: 종영 | G11: 16917 | H11: 36952 | I11: 104 | J11: 3998 | K11: =IFERROR(G11/H11,"") | L11: =IFERROR(J11/H11,"") | M11: 104 | N11: 88 | O11: 250 | P11: 3 | Q11: 2024-05-27 | R11: 2024-06-16 | S11: 애니메이션 | T11: 미국 | U11: 월트디즈니컴퍼니코리아 유한책임회사
A12: 첫여름 | B12: 2025-08-06 | D12: 재개봉/구작 | E12: 실사 한국 | F12: 종영 | G12: 16906 | H12: 13702 | I12: 85 | J12: 1595 | K12: =IFERROR(G12/H12,"") | L12: =IFERROR(J12/H12,"") | M12: 85 | N12: 32.3 | O12: 132 | P12: 10 | Q12: 2025-07-28 | R12: 2025-10-05 | S12: 드라마 | T12: 한국 | U12: 한국영화아카데미
A13: 가타카 | B13: 2025-11-20 | C13: 1998-05-02 | D13: 재개봉/구작 | E13: 실사 외화 | F13: 종영 | G13: 16560 | H13: 15383 | I13: 71 | J13: 1388 | K13: =IFERROR(G13/H13,"") | L13: =IFERROR(J13/H13,"") | M13: 72 | N13: 26.7 | O13: 148 | P13: 7 | Q13: 2025-11-17 | R13: 2026-01-04 | S13: SF,드라마,미스터리,스릴러 | T13: 미국
A14: 중경삼림 | B14: 2024-02-14 | C14: 1995-09-02 | D14: 재개봉/구작 | E14: 실사 외화 | F14: 종영 | G14: 16102 | H14: 6776 | I14: 53 | J14: 1390 | K14: =IFERROR(G14/H14,"") | L14: =IFERROR(J14/H14,"") | M14: 53 | N14: 11.3 | O14: 111 | P14: 14 | Q14: 2024-02-12 | R14: 2024-05-19 | S14: 드라마 | T14: 홍콩 | U14: (주)디스테이션
A15: 해피 투게더 | B15: 2023-03-30 | C15: 1998-08-22 | D15: 재개봉/구작 | E15: 실사 외화 | F15: 종영 | G15: 15835 | H15: 36350 | I15: 140 | J15: 7147 | K15: =IFERROR(G15/H15,"") | L15: =IFERROR(J15/H15,"") | M15: 129 | N15: 42.1 | O15: 186 | P15: 5 | Q15: 2023-03-27 | R15: 2023-04-30 | S15: 드라마,멜로/로맨스 | T15: 홍콩 | U15: (주)디스테이션
A16: 철도원 | B16: 2026-01-07 | C16: 2000-02-04 | D16: 재개봉/구작 | E16: 실사 외화 | F16: 종영 | G16: 14997 | H16: 24542 | I16: 127 | J16: 1289 | K16: =IFERROR(G16/H16,"") | L16: =IFERROR(J16/H16,"") | M16: 123 | N16: 53.5 | O16: 147 | P16: 5 | Q16: 2026-01-05 | R16: 2026-02-08 | S16: 가족,드라마 | T16: 일본 | U16: 와이드 릴리즈(주)
A17: 슈퍼소닉 | B17: 2025-08-29 | C17: 2016-11-24 | D17: 재개봉/구작 | E17: 실사 외화 | F17: 종영 | G17: 14607 | H17: 25786 | I17: 124 | J17: 3774 | K17: =IFERROR(G17/H17,"") | L17: =IFERROR(J17/H17,"") | M17: 93 | N17: 39.8 | O17: 158 | P17: 6 | Q17: 2025-08-18 | R17: 2025-09-28 | S17: 다큐멘터리 | T17: 영국 | U17: (주)레드아이스 엔터테인먼트,주식회사 씨네룩스
A18: 크리스마스에 기적을 만날 확률 | B18: 2024-12-11 | C18: 2007-12-12 | D18: 재개봉/구작 | E18: 애니메이션 | F18: 종영 | G18: 13312 | H18: 21229 | I18: 117 | J18: 1827 | K18: =IFERROR(G18/H18,"") | L18: =IFERROR(J18/H18,"") | M18: 110 | N18: 35.6 | O18: 139 | P18: 7 | Q18: 2024-12-09 | R18: 2025-01-26 | S18: 애니메이션,드라마,액션 | T18: 일본 | U18: (주)팝엔터테인먼트,롯데쇼핑㈜롯데엔터테인먼트
A19: 택시 드라이버 | B19: 2025-04-09 | C19: 1989-02-17 | D19: 재개봉/구작 | E19: 실사 외화 | F19: 종영 | G19: 10856 | H19: 20556 | I19: 82 | J19: 2006 | K19: =IFERROR(G19/H19,"") | L19: =IFERROR(J19/H19,"") | M19: 83 | N19: 61.7 | O19: 164 | P19: 4 | Q19: 2025-04-07 | R19: 2025-05-04 | S19: 드라마,스릴러 | T19: 미국
A20: 레옹 | B20: 2024-04-22 | C20: 1995-02-18 | D20: 재개봉/구작 | E20: 실사 외화 | F20: 종영 | G20: 10030 | H20: 18828 | I20: 94 | J20: 1129 | K20: =IFERROR(G20/H20,"") | L20: =IFERROR(J20/H20,"") | M20: 88 | N20: 20.9 | O20: 140 | P20: 5 | Q20: 2024-04-22 | R20: 2024-05-26 | S20: 액션,범죄 | T20: 프랑스 | U20: 와이드 릴리즈(주),(주)제이앤씨미디어그룹,(주)팝파트너스
A21: 그랜드 부다페스트 호텔 | B21: 2026-04-08 | C21: 2014-03-20 | D21: 재개봉/구작 | E21: 실사 외화 | F21: 종영 | G21: 9624 | H21: 20307 | I21: 81 | J21: 3077 | K21: =IFERROR(G21/H21,"") | L21: =IFERROR(J21/H21,"") | M21: 81 | N21: 23.8 | O21: 190 | P21: 5 | Q21: 2026-04-06 | R21: 2026-05-10 | S21: 미스터리,어드벤처 | T21: 미국 | U21: (주)피터팬픽쳐스,이십세기폭스코리아(주),월트디즈니컴퍼니코리아 유한책임회사
A22: 라이프 오브 파이 | B22: 2026-03-25 | C22: 2013-01-01 | D22: 재개봉/구작 | E22: 실사 외화 | F22: 종영 | G22: 9540 | H22: 16920 | I22: 58 | J22: 3065 | K22: =IFERROR(G22/H22,"") | L22: =IFERROR(J22/H22,"") | M22: 58 | N22: 26 | O22: 214 | P22: 4 | Q22: 2026-03-23 | R22: 2026-04-19 | S22: 어드벤처,드라마 | T22: 미국 | U22: 월트디즈니컴퍼니코리아 유한책임회사,주식회사 해리슨앤컴퍼니,이십세기폭스코리아(주)
A23: 366일 | B23: 2025-06-11 | D23: 재개봉/구작 | E23: 실사 외화 | F23: 종영 | G23: 9120 | H23: 25550 | I23: 134 | J23: 1138 | K23: =IFERROR(G23/H23,"") | L23: =IFERROR(J23/H23,"") | M23: 133 | N23: 43.9 | O23: 151 | P23: 5 | Q23: 2025-06-09 | R23: 2025-07-13 | S23: 멜로/로맨스 | T23: 몽고
A24: 우마무스메 프리티 더비 로드 투 더 탑 | B24: 2024-06-27 | D24: 재개봉/구작 | E24: 애니메이션 | F24: 종영 | G24: 8135 | H24: 13305 | I24: 64 | J24: 2741 | K24: =IFERROR(G24/H24,"") | L24: =IFERROR(J24/H24,"") | M24: 64 | N24: 44.2 | O24: 161 | P24: 3 | Q24: 2024-06-24 | R24: 2024-07-14 | S24: 애니메이션 | T24: 일본 | U24: (주)애니플러스
A25: 스타 이즈 본 | B25: 2023-11-29 | C25: 2018-10-09 | D25: 재개봉/구작 | E25: 실사 외화 | F25: 종영 | G25: 6925 | H25: 19370 | I25: 52 | J25: 1766 | K25: =IFERROR(G25/H25,"") | L25: =IFERROR(J25/H25,"") | M25: 53 | N25: 27.9 | O25: 242 | P25: 3 | Q25: 2023-11-27 | R25: 2023-12-17 | S25: 드라마,멜로/로맨스 | T25: 미국 | U25: 워너브러더스 코리아(주)
A26: 화양연화 | B26: 2024-02-14 | C26: 2000-10-20 | D26: 재개봉/구작 | E26: 실사 외화 | F26: 종영 | G26: 6706 | H26: 6629 | I26: 50 | J26: 1232 | K26: =IFERROR(G26/H26,"") | L26: =IFERROR(J26/H26,"") | M26: 50 | N26: 38.1 | O26: 129 | P26: 3 | Q26: 2024-02-12 | R26: 2024-03-03 | S26: 드라마,멜로/로맨스 | T26: 홍콩 | U26: (주)디스테이션
A27: 카우보이 비밥-천국의문 | B27: 2025-04-25 | C27: 2003-10-03 | D27: 재개봉/구작 | E27: 애니메이션 | F27: 종영 | G27: 6705 | H27: 20774 | I27: 89 | J27: 1473 | K27: =IFERROR(G27/H27,"") | L27: =IFERROR(J27/H27,"") | M27: 89 | N27: 43.7 | O27: 144 | P27: 5 | Q27: 2025-04-21 | R27: 2025-05-25 | S27: 애니메이션,액션 | T27: 일본 | U27: 콜럼비아트라이스타㈜
A28: 단다단: 사안 | B28: 2025-06-05 | D28: 재개봉/구작 | E28: 애니메이션 | F28: 종영 | G28: 6504 | H28: 12363 | I28: 66 | J28: 1419 | K28: =IFERROR(G28/H28,"") | L28: =IFERROR(J28/H28,"") | M28: 65 | N28: 39.2 | O28: 137 | P28: 4 | Q28: 2025-06-02 | R28: 2025-06-29 | S28: 애니메이션 | T28: 일본 | U28: (주)애니플러스
A29: 헤드윅 | B29: 2023-12-06 | C29: 2002-08-09 | D29: 재개봉/구작 | E29: 공연·실황 | F29: 종영 | G29: 6280 | H29: 11909 | I29: 59 | J29: 2552 | K29: =IFERROR(G29/H29,"") | L29: =IFERROR(J29/H29,"") | M29: 59 | N29: 45.4 | O29: 157 | P29: 3 | Q29: 2023-12-04 | R29: 2023-12-24 | S29: 뮤지컬 | T29: 미국 | U29: 워너브러더스 코리아(주),(주)엣나인필름,(주)씨네월드
A30: 아이언맨 | B30: 2024-10-09 | C30: 2008-04-30 | D30: 재개봉/구작 | E30: 실사 외화 | F30: 종영 | G30: 5944 | H30: 18444 | I30: 88 | J30: 2924 | K30: =IFERROR(G30/H30,"") | L30: =IFERROR(J30/H30,"") | M30: 88 | N30: 50.4 | O30: 173 | P30: 3 | Q30: 2024-10-07 | R30: 2024-10-27 | S30: SF,드라마,액션 | T30: 미국 | U30: 씨제이엔터테인먼트
A31: 5등분의 신부 스페셜 | B31: 2023-10-12 | D31: 재개봉/구작 | E31: 애니메이션 | F31: 종영 | G31: 5854 | H31: 13124 | I31: 69 | J31: 833 | K31: =IFERROR(G31/H31,"") | L31: =IFERROR(J31/H31,"") | M31: 69 | N31: 36.7 | O31: 155 | P31: 4 | Q31: 2023-10-09 | R31: 2023-11-05 | S31: 애니메이션 | T31: 일본
A32: 지리멸렬 | B32: 2025-08-27 | D32: 재개봉/구작 | E32: 실사 한국 | F32: 종영 | G32: 5268 | H32: 11813 | I32: 88 | J32: 783 | K32: =IFERROR(G32/H32,"") | L32: =IFERROR(J32/H32,"") | M32: 87 | N32: 45.2 | O32: 123 | P32: 5 | Q32: 2025-08-25 | R32: 2025-09-28 | S32: 코미디 | T32: 한국 | U32: ㈜인디스토리
A33: 기쿠지로의 여름 | B33: 2024-07-03 | C33: 2002-08-30 | D33: 재개봉/구작 | E33: 실사 외화 | F33: 종영 | G33: 5186 | H33: 8163 | I33: 59 | J33: 1024 | K33: =IFERROR(G33/H33,"") | L33: =IFERROR(J33/H33,"") | M33: 59 | N33: 18.8 | O33: 131 | P33: 5 | Q33: 2024-07-01 | R33: 2024-08-04 | S33: 코미디 | T33: 일본 | U33: (주)영화사 진진,(주)튜브엔터테인먼트
A34: 렛 미 인 | B34: 2025-01-15 | C34: 2010-11-18 | D34: 재개봉/구작 | E34: 실사 외화 | F34: 종영 | G34: 5160 | H34: 24909 | I34: 116 | J34: 682 | K34: =IFERROR(G34/H34,"") | L34: =IFERROR(J34/H34,"") | M34: 112 | N34: 28.5 | O34: 171 | P34: 6 | Q34: 2025-01-06 | R34: 2025-02-16 | S34: 드라마,판타지,공포(호러),미스터리 | T34: 영국 | U34: 롯데쇼핑㈜롯데엔터테인먼트
A35: 영웅본색 | B35: 2024-03-27 | C35: 1987-05-23 | D35: 재개봉/구작 | E35: 실사 외화 | F35: 종영 | G35: 5154 | H35: 8172 | I35: 61 | J35: 911 | K35: =IFERROR(G35/H35,"") | L35: =IFERROR(J35/H35,"") | M35: 61 | N35: 23.6 | O35: 135 | P35: 5 | Q35: 2024-03-25 | R35: 2024-04-28 | S35: 액션,범죄 | T35: 홍콩 | U35: (주)제이앤씨미디어그룹,와이드 릴리즈(주),(유)조이앤시네마
A36: 클래식 | B36: 2024-07-03 | C36: 2003-01-30 | D36: 재개봉/구작 | E36: 실사 한국 | F36: 종영 | G36: 5098 | H36: 7339 | I36: 53 | J36: 1065 | K36: =IFERROR(G36/H36,"") | L36: =IFERROR(J36/H36,"") | M36: 53 | N36: 11 | O36: 127 | P36: 7 | Q36: 2024-07-01 | R36: 2024-08-18 | S36: 드라마 | T36: 한국 | U36: (주)시네마서비스,(주)씨제이이엔엠
A37: 아이언맨 3 | B37: 2024-10-09 | C37: 2013-04-25 | D37: 재개봉/구작 | E37: 실사 외화 | F37: 종영 | G37: 4494 | H37: 16028 | I37: 88 | J37: 1009 | K37: =IFERROR(G37/H37,"") | L37: =IFERROR(J37/H37,"") | M37: 88 | N37: 49 | O37: 166 | P37: 3 | Q37: 2024-10-07 | R37: 2024-10-27 | S37: 액션,어드벤처,SF | T37: 미국 | U37: 소니픽쳐스릴리징월트디즈니스튜디오스코리아(주)
A38: 8월의 크리스마스 | B38: 2024-04-17 | C38: 1998-01-24 | D38: 재개봉/구작 | E38: 실사 한국 | F38: 종영 | G38: 4426 | H38: 8260 | I38: 59 | J38: 433 | K38: =IFERROR(G38/H38,"") | L38: =IFERROR(J38/H38,"") | M38: 70 | N38: 21.4 | O38: 145 | P38: 5 | Q38: 2024-04-15 | R38: 2024-05-19 | S38: 멜로/로맨스,드라마 | T38: 한국 | U38: 한국영상투자개발(주),(주)싸이더스
A39: 라라랜드 | B39: 2023-04-18 | C39: 2016-12-07 | D39: 재개봉/구작 | E39: 공연·실황 | F39: 종영 | G39: 3751 | H39: 7811 | I39: 50 | J39: 875 | K39: =IFERROR(G39/H39,"") | L39: =IFERROR(J39/H39,"") | M39: 50 | N39: 19.2 | O39: 167 | P39: 4 | Q39: 2023-04-03 | R39: 2023-04-30 | S39: 드라마,뮤지컬,멜로/로맨스 | T39: 미국 | U39: 판씨네마(주)
A40: 시애틀의 잠 못이루는 밤 | B40: 2024-12-11 | C40: 1993-12-18 | D40: 재개봉/구작 | E40: 실사 외화 | F40: 종영 | G40: 3521 | H40: 7134 | I40: 58 | J40: 672 | K40: =IFERROR(G40/H40,"") | L40: =IFERROR(J40/H40,"") | M40: 57 | N40: 42.7 | O40: 111 | P40: 3 | Q40: 2024-12-09 | R40: 2024-12-29 | S40: 드라마,멜로/로맨스 | T40: 미국 | U40: (주)디스테이션
...

Sheet 인더그레이 밴드
A1: ※ 인 더 그레이(2026-09-02, 실사 외화, 메가박스 단독)의 최근접 comp = 실사 외화 × 메가 최대주간 150관 이상.
A2: 영화명 | B2: 개봉일 | C2: 원개봉일 | D2: 구분 | E2: 세그먼트 | F2: 상영상태 | G2: 누적관객 | H2: 개봉일좌석수 | I2: 개봉일스크린수 | J2: 개봉일관객수 | K2: 배수(누적÷개봉일좌석) | L2: 개봉일 좌석판매율 | M2: 메가최대일간스크린 | N2: 평균스크린 | O2: 스크린당좌석 | P2: 상영주수 | Q2: 단독런시작 | R2: 단독런종료 | S2: 장르 | T2: 대표국적 | U2: 배급사
A3: 머티리얼리스트 | B3: 2025-08-08 | C3: 2025-08-08 | D3: 신작 | E3: 실사 외화 | F3: 종영 | G3: 63767 | H3: 62670 | I3: 166 | J3: 7585 | K3: =IFERROR(G3/H3,"") | L3: =IFERROR(J3/H3,"") | M3: 157 | N3: 63.6 | O3: 213 | P3: 9 | Q3: 2025-07-28 | R3: 2025-09-28 | S3: 멜로/로맨스,코미디 | T3: 미국 | U3: 소니픽쳐스엔터테인먼트코리아주식회사극장배급지점
A4: 첫 번째 키스 | B4: 2025-02-26 | C4: 2025-02-26 | D4: 신작 | E4: 실사 외화 | F4: 종영 | G4: 49143 | H4: 61274 | I4: 184 | J4: 6199 | K4: =IFERROR(G4/H4,"") | L4: =IFERROR(J4/H4,"") | M4: 178 | N4: 64.2 | O4: 208 | P4: 8 | Q4: 2025-02-24 | R4: 2025-04-20 | S4: 드라마,멜로/로맨스 | T4: 일본 | U4: 메가박스중앙(주)
A5: 워킹맨 | B5: 2025-10-01 | C5: 2025-10-01 | D5: 신작 | E5: 실사 외화 | F5: 종영 | G5: 21014 | H5: 52983 | I5: 173 | J5: 4459 | K5: =IFERROR(G5/H5,"") | L5: =IFERROR(J5/H5,"") | M5: 172 | N5: 46.5 | O5: 181 | P5: 7 | Q5: 2025-09-29 | R5: 2025-11-16 | S5: 액션,스릴러,범죄 | T5: 미국 | U5: 메가박스중앙(주),(주)스튜디오디에이치엘
A6: 크라임 101 | B6: 2026-04-08 | C6: 2026-04-08 | D6: 신작 | E6: 실사 외화 | F6: 종영 | G6: 20138 | H6: 53148 | I6: 208 | J6: 3513 | K6: =IFERROR(G6/H6,"") | L6: =IFERROR(J6/H6,"") | M6: 171 | N6: 75.2 | O6: 210 | P6: 6 | Q6: 2026-03-30 | R6: 2026-05-10 | S6: 범죄,드라마,스릴러 | T6: 미국 | U6: 소니픽쳐스엔터테인먼트코리아주식회사극장배급지점
A7: 더 로즈: 완벽한 이혼 | B7: 2025-09-17 | C7: 2025-09-17 | D7: 신작 | E7: 실사 외화 | F7: 종영 | G7: 18670 | H7: 54406 | I7: 167 | J7: 3185 | K7: =IFERROR(G7/H7,"") | L7: =IFERROR(J7/H7,"") | M7: 152 | N7: 77 | O7: 208 | P7: 6 | Q7: 2025-09-08 | R7: 2025-10-19 | S7: 코미디,드라마 | T7: 미국 | U7: 월트디즈니컴퍼니코리아 유한책임회사
A8: 워페어 | B8: 2026-08-19 | C8: 2026-08-19 | D8: 신작 | E8: 실사 외화 | F8: 상영중(잠정) | G8: 17119 | H8: 45012 | I8: 199 | J8: 3815 | K8: =IFERROR(G8/H8,"") | L8: =IFERROR(J8/H8,"") | M8: 188 | N8: 115.9 | O8: 176 | P8: 4 | Q8: 2026-08-03 | R8: 2026-08-30 | S8: 액션,드라마,전쟁 | T8: 미국 | U8: 주식회사 올랄라스토리
